{
  "version": 8,
  "blockIdVersion": 11,
  "anchorX": 0,
  "anchorY": 0,
  "anchorZ": 0,
  "blocks": [
    {
      "x": -3,
      "y": 4,
      "z": 0,
      "name": "Plant_Leaves_AncientWillow"
    },
    {
      "x": -2,
      "y": 4,
      "z": -2,
      "name": "Plant_Leaves_AncientWillow"
    },
    {
      "x": -2,
      "y": 4,
      "z": -1,
      "name": "Plant_Leaves_AncientWillow"
    },
    {
      "x": -2,
      "y": 3,
      "z": 0,
      "name": "Plant_Leaves_AncientWillow"
    },
    {
      "x": -2,
      "y": 4,
      "z": 0,
      "name": "Wood_AncientWillow_Branch_Long",
      "rotation": 5
    },
    {
      "x": -2,
      "y": 5,
      "z": 0,
      "name": "Plant_Leaves_AncientWillow"
    },
    {
      "x": -2,
      "y": 4,
      "z": 1,
      "name": "Plant_Leaves_AncientWillow"
    },
    {
      "x": -2,
      "y": 5,
      "z": 1,
      "name": "Plant_Leaves_AncientWillow"
    },
    {
      "x": -2,
      "y": 6,
      "z": 1,
      "name": "Plant_Leaves_AncientWillow"
    },
    {
      "x": -2,
      "y": 4,
      "z": 2,
      "name": "Plant_Leaves_AncientWillow"
    },
    {
      "x": -2,
      "y": 4,
      "z": 3,
      "name": "Plant_Leaves_AncientWillow"
    },
    {
      "x": -2,
      "y": 4,
      "z": 4,
      "name": "Plant_Leaves_AncientWillow"
    },
    {
      "x": -1,
      "y": 4,
      "z": -4,
      "name": "Plant_Leaves_AncientWillow"
    },
    {
      "x": -1,
      "y": 4,
      "z": -3,
      "name": "Plant_Leaves_AncientWillow"
    },
    {
      "x": -1,
      "y": 4,
      "z": -2,
      "name": "Wood_AncientWillow_Branch_Long",
      "rotation": 4
    },
    {
      "x": -1,
      "y": 5,
      "z": -2,
      "name": "Plant_Leaves_AncientWillow"
    },
    {
      "x": -1,
      "y": 4,
      "z": -1,
      "name": "Wood_AncientWillow_Trunk_Full"
    },
    {
      "x": -1,
      "y": 5,
      "z": -1,
      "name": "Plant_Leaves_AncientWillow"
    },
    {
      "x": -1,
      "y": 1,
      "z": 0,
      "name": "Wood_AncientWillow_Branch_Corner",
      "rotation": 3
    },
    {
      "x": -1,
      "y": 2,
      "z": 0,
      "name": "Wood_AncientWillow_Trunk_Full"
    },
    {
      "x": -1,
      "y": 3,
      "z": 0,
      "name": "Wood_AncientWillow_Trunk"
    },
    {
      "x": -1,
      "y": 4,
      "z": 0,
      "name": "Wood_AncientWillow_Trunk_Full"
    },
    {
      "x": -1,
      "y": 5,
      "z": 0,
      "name": "Plant_Leaves_AncientWillow"
    },
    {
      "x": -1,
      "y": 3,
      "z": 1,
      "name": "Plant_Leaves_AncientWillow"
    },
    {
      "x": -1,
      "y": 4,
      "z": 1,
      "name": "Wood_AncientWillow_Trunk_Full"
    },
    {
      "x": -1,
      "y": 5,
      "z": 1,
      "name": "Wood_AncientWillow_Trunk"
    },
    {
      "x": -1,
      "y": 6,
      "z": 1,
      "name": "Wood_AncientWillow_Branch_Long"
    },
    {
      "x": -1,
      "y": 7,
      "z": 1,
      "name": "Plant_Leaves_AncientWillow"
    },
    {
      "x": -1,
      "y": 3,
      "z": 2,
      "name": "Plant_Leaves_AncientWillow"
    },
    {
      "x": -1,
      "y": 4,
      "z": 2,
      "name": "Wood_AncientWillow_Trunk_Full",
      "rotation": 4
    },
    {
      "x": -1,
      "y": 5,
      "z": 2,
      "name": "Plant_Leaves_AncientWillow"
    },
    {
      "x": -1,
      "y": 6,
      "z": 2,
      "name": "Plant_Leaves_AncientWillow"
    },
    {
      "x": -1,
      "y": 3,
      "z": 3,
      "name": "Plant_Leaves_AncientWillow"
    },
    {
      "x": -1,
      "y": 4,
      "z": 3,
      "name": "Wood_AncientWillow_Branch_Long",
      "rotation": 4
    },
    {
      "x": -1,
      "y": 5,
      "z": 3,
      "name": "Plant_Leaves_AncientWillow"
    },
    {
      "x": -1,
      "y": 2,
      "z": 4,
      "name": "Plant_Leaves_AncientWillow"
    },
    {
      "x": -1,
      "y": 3,
      "z": 4,
      "name": "Plant_Leaves_AncientWillow"
    },
    {
      "x": -1,
      "y": 4,
      "z": 4,
      "name": "Wood_AncientWillow_Branch_Corner"
    },
    {
      "x": -1,
      "y": 5,
      "z": 4,
      "name": "Plant_Leaves_AncientWillow"
    },
    {
      "x": -1,
      "y": 4,
      "z": 5,
      "name": "Plant_Leaves_AncientWillow"
    },
    {
      "x": 0,
      "y": 2,
      "z": -5,
      "name": "Plant_Leaves_AncientWillow"
    },
    {
      "x": 0,
      "y": 3,
      "z": -5,
      "name": "Plant_Leaves_AncientWillow"
    },
    {
      "x": 0,
      "y": 4,
      "z": -5,
      "name": "Plant_Leaves_AncientWillow"
    },
    {
      "x": 0,
      "y": 3,
      "z": -4,
      "name": "Plant_Leaves_AncientWillow"
    },
    {
      "x": 0,
      "y": 4,
      "z": -4,
      "name": "Wood_AncientWillow_Trunk_Full",
      "rotation": 4
    },
    {
      "x": 0,
      "y": 5,
      "z": -4,
      "name": "Plant_Leaves_AncientWillow"
    },
    {
      "x": 0,
      "y": 4,
      "z": -3,
      "name": "Plant_Leaves_AncientWillow"
    },
    {
      "x": 0,
      "y": 4,
      "z": -1,
      "name": "Plant_Leaves_AncientWillow"
    },
    {
      "x": 0,
      "y": 0,
      "z": 0,
      "name": "Wood_AncientWillow_Trunk"
    },
    {
      "x": 0,
      "y": 1,
      "z": 0,
      "name": "Wood_AncientWillow_Trunk"
    },
    {
      "x": 0,
      "y": 2,
      "z": 0,
      "name": "Wood_AncientWillow_Trunk_Full"
    },
    {
      "x": 0,
      "y": 4,
      "z": 0,
      "name": "Plant_Leaves_AncientWillow"
    },
    {
      "x": 0,
      "y": 4,
      "z": 1,
      "name": "Plant_Leaves_AncientWillow"
    },
    {
      "x": 0,
      "y": 5,
      "z": 1,
      "name": "Plant_Leaves_AncientWillow"
    },
    {
      "x": 0,
      "y": 6,
      "z": 1,
      "name": "Plant_Leaves_AncientWillow"
    },
    {
      "x": 0,
      "y": 3,
      "z": 2,
      "name": "Plant_Leaves_AncientWillow"
    },
    {
      "x": 0,
      "y": 4,
      "z": 2,
      "name": "Wood_AncientWillow_Trunk_Full",
      "rotation": 5
    },
    {
      "x": 0,
      "y": 5,
      "z": 2,
      "name": "Plant_Leaves_AncientWillow"
    },
    {
      "x": 0,
      "y": 4,
      "z": 3,
      "name": "Plant_Leaves_AncientWillow"
    },
    {
      "x": 0,
      "y": 4,
      "z": 4,
      "name": "Plant_Leaves_AncientWillow"
    },
    {
      "x": 1,
      "y": 4,
      "z": -4,
      "name": "Plant_Leaves_AncientWillow"
    },
    {
      "x": 1,
      "y": 3,
      "z": -3,
      "name": "Plant_Leaves_AncientWillow"
    },
    {
      "x": 1,
      "y": 4,
      "z": -3,
      "name": "Wood_AncientWillow_Trunk_Full",
      "rotation": 4
    },
    {
      "x": 1,
      "y": 5,
      "z": -3,
      "name": "Plant_Leaves_AncientWillow"
    },
    {
      "x": 1,
      "y": 3,
      "z": -2,
      "name": "Plant_Leaves_AncientWillow"
    },
    {
      "x": 1,
      "y": 4,
      "z": -2,
      "name": "Plant_Leaves_AncientWillow"
    },
    {
      "x": 1,
      "y": 2,
      "z": -1,
      "name": "Wood_AncientWillow_Trunk_Full"
    },
    {
      "x": 1,
      "y": 3,
      "z": -1,
      "name": "Wood_AncientWillow_Trunk_Full"
    },
    {
      "x": 1,
      "y": 4,
      "z": -1,
      "name": "Plant_Leaves_AncientWillow"
    },
    {
      "x": 1,
      "y": 4,
      "z": 1,
      "name": "Plant_Leaves_AncientWillow"
    },
    {
      "x": 1,
      "y": 2,
      "z": 2,
      "name": "Plant_Leaves_AncientWillow"
    },
    {
      "x": 1,
      "y": 3,
      "z": 2,
      "name": "Plant_Leaves_AncientWillow"
    },
    {
      "x": 1,
      "y": 4,
      "z": 2,
      "name": "Wood_AncientWillow_Trunk_Full",
      "rotation": 5
    },
    {
      "x": 1,
      "y": 5,
      "z": 2,
      "name": "Plant_Leaves_AncientWillow"
    },
    {
      "x": 1,
      "y": 4,
      "z": 3,
      "name": "Plant_Leaves_AncientWillow"
    },
    {
      "x": 2,
      "y": 4,
      "z": -3,
      "name": "Plant_Leaves_AncientWillow"
    },
    {
      "x": 2,
      "y": 2,
      "z": -2,
      "name": "Plant_Leaves_AncientWillow"
    },
    {
      "x": 2,
      "y": 3,
      "z": -2,
      "name": "Wood_AncientWillow_Trunk_Full"
    },
    {
      "x": 2,
      "y": 4,
      "z": -2,
      "name": "Wood_AncientWillow_Trunk_Full"
    },
    {
      "x": 2,
      "y": 5,
      "z": -2,
      "name": "Plant_Leaves_AncientWillow"
    },
    {
      "x": 2,
      "y": 3,
      "z": -1,
      "name": "Plant_Leaves_AncientWillow"
    },
    {
      "x": 2,
      "y": 4,
      "z": -1,
      "name": "Wood_AncientWillow_Branch_Long",
      "rotation": 4
    },
    {
      "x": 2,
      "y": 5,
      "z": -1,
      "name": "Plant_Leaves_AncientWillow"
    },
    {
      "x": 2,
      "y": 3,
      "z": 0,
      "name": "Plant_Leaves_AncientWillow"
    },
    {
      "x": 2,
      "y": 3,
      "z": 1,
      "name": "Plant_Leaves_AncientWillow"
    },
    {
      "x": 2,
      "y": 2,
      "z": 2,
      "name": "Plant_Leaves_AncientWillow"
    },
    {
      "x": 2,
      "y": 3,
      "z": 2,
      "name": "Wood_AncientWillow_Trunk_Full",
      "rotation": 5
    },
    {
      "x": 2,
      "y": 4,
      "z": 2,
      "name": "Plant_Leaves_AncientWillow"
    },
    {
      "x": 2,
      "y": 3,
      "z": 3,
      "name": "Plant_Leaves_AncientWillow"
    },
    {
      "x": 3,
      "y": 5,
      "z": -4,
      "name": "Plant_Leaves_AncientWillow"
    },
    {
      "x": 3,
      "y": 4,
      "z": -3,
      "name": "Plant_Leaves_AncientWillow"
    },
    {
      "x": 3,
      "y": 5,
      "z": -3,
      "name": "Wood_AncientWillow_Trunk_Full",
      "rotation": 5
    },
    {
      "x": 3,
      "y": 6,
      "z": -3,
      "name": "Plant_Leaves_AncientWillow"
    },
    {
      "x": 3,
      "y": 3,
      "z": -2,
      "name": "Plant_Leaves_AncientWillow"
    },
    {
      "x": 3,
      "y": 4,
      "z": -2,
      "name": "Plant_Leaves_AncientWillow"
    },
    {
      "x": 3,
      "y": 5,
      "z": -2,
      "name": "Plant_Leaves_AncientWillow"
    },
    {
      "x": 3,
      "y": 4,
      "z": -1,
      "name": "Plant_Leaves_AncientWillow"
    },
    {
      "x": 3,
      "y": 3,
      "z": 1,
      "name": "Plant_Leaves_AncientWillow"
    },
    {
      "x": 3,
      "y": 2,
      "z": 2,
      "name": "Plant_Leaves_AncientWillow"
    },
    {
      "x": 3,
      "y": 3,
      "z": 2,
      "name": "Wood_AncientWillow_Branch_Long",
      "rotation": 5
    },
    {
      "x": 3,
      "y": 4,
      "z": 2,
      "name": "Plant_Leaves_AncientWillow"
    },
    {
      "x": 3,
      "y": 3,
      "z": 3,
      "name": "Plant_Leaves_AncientWillow"
    },
    {
      "x": 4,
      "y": 5,
      "z": -3,
      "name": "Plant_Leaves_AncientWillow"
    },
    {
      "x": 4,
      "y": 3,
      "z": 2,
      "name": "Plant_Leaves_AncientWillow"
    }
  ]
}
